<?xml version="1.0"?>
<sdf version="1.8">
    <model name="hexrotor">
        <pose>0 0 0.121078 0 0 0</pose>
        <link name="base_link">
            <enable_wind>true</enable_wind>
            <pose>0 0 0 0 -0 0</pose>
            <inertial>
                <pose>0 0 0 0 -0 0</pose>
                <mass>3.42</mass>
                <inertia>
                    <ixx>0.075</ixx>
                    <ixy>0</ixy>
                    <ixz>0</ixz>
                    <iyy>0.075</iyy>
                    <iyz>0</iyz>
                    <izz>0.148916</izz>
                </inertia>
            </inertial>
            <collision name="base_link_inertia_collision">
                <pose>0 0 0.025 0 -0 0</pose>
                <geometry>
                    <box>
                        <size>0.3 0.3 0.12</size>
                    </box>
                </geometry>
            </collision>
            <collision name="leg_0">
                <pose>0.102415 -0.064721 -0.046935 -0.453199 -0.358392 0.452524</pose>
                <geometry>
                    <cylinder>
                        <length>0.173859</length>
                        <radius>0.010630</radius>
                    </cylinder>
                </geometry>
            </collision>
             <collision name="leg_1">
                <pose>0.102415 0.064721 -0.046935 0.453199 -0.358392 -0.452524</pose>
                <geometry>
                    <cylinder>
                        <length>0.173859</length>
                        <radius>0.010630</radius>
                    </cylinder>
                </geometry>
            </collision>
            <collision name="leg_2">
                <pose>-0.110415 0.086683 -0.046935 2.8230806 -0.369254 -2.921386</pose>
                <geometry>
                    <cylinder>
                        <length>0.173859</length>
                        <radius>0.010630</radius>
                    </cylinder>
                </geometry>
            </collision>
             <collision name="leg_3">
                <pose>-0.110415 -0.086683 -0.046935 -2.8230806 -0.369254 2.921386</pose>
                <geometry>
                    <cylinder>
                        <length>0.173859</length>
                        <radius>0.010630</radius>
                    </cylinder>
                </geometry>
            </collision>

            <visual name="base_link_inertia_visual">
                <pose>0 0 0 0 -0 0</pose>
                <geometry>
                    <mesh>
                        <scale>1 1 1</scale>
                        <uri>model://hexrotor_base/meshes/hexrotor.dae</uri>
                    </mesh>
                </geometry>
            </visual>
            <visual name="marker_visual_1">
                <pose>-0.1 0 0.077 0 -0.1 0</pose>
                <geometry>
                    <mesh>
                        <scale>1 1 1</scale>
                        <uri>model://hexrotor_base/meshes/led.dae</uri>
                    </mesh>
                </geometry>
            </visual>
            <visual name="marker_visual_2">
                <pose>-0.09 0.059 0.059 -0.785397 -0 0.2</pose>
                <geometry>
                    <mesh>
                        <scale>1 1 1</scale>
                        <uri>model://hexrotor_base/meshes/led.dae</uri>
                    </mesh>
                </geometry>
            </visual>
            <visual name="marker_visual_3">
                <pose>-0.09 -0.059 0.059 0.785397 -0 -0.2</pose>
                <geometry>
                    <mesh>
                        <scale>1 1 1</scale>
                        <uri>model://hexrotor_base/meshes/led.dae</uri>
                    </mesh>
                </geometry>
            </visual>
        </link>

        <!-- IMU -->
        <model name='imu'>
            <link name="internal">
                <inertial>
                    <mass>0.005</mass>
                    <inertia>
                        <ixx>8.33e-06</ixx>
                        <ixy>0</ixy>
                        <ixz>0</ixz>
                        <iyy>8.33e-06</iyy>
                        <iyz>0</iyz>
                        <izz>8.33e-06</izz>
                    </inertia>
                </inertial>
                <sensor name='imu' type='imu'>
                    <always_on>1</always_on>
                    <update_rate>250</update_rate>
                    <imu>
                        <angular_velocity>
                            <x>
                                <noise type='gaussian'>
                                    <mean>0</mean>
                                    <stddev>0.009</stddev>
                                    <bias_mean>0.00075</bias_mean>
                                    <bias_stddev>0.005</bias_stddev>
                                    <dynamic_bias_stddev>0.00002</dynamic_bias_stddev>
                                    <dynamic_bias_correlation_time>400.0</dynamic_bias_correlation_time>
                                    <precision>0.00025</precision>
                                </noise>
                            </x>
                            <y>
                                <noise type='gaussian'>
                                    <mean>0</mean>
                                    <stddev>0.009</stddev>
                                    <bias_mean>0.00075</bias_mean>
                                    <bias_stddev>0.005</bias_stddev>
                                    <dynamic_bias_stddev>0.00002</dynamic_bias_stddev>
                                    <dynamic_bias_correlation_time>400.0</dynamic_bias_correlation_time>
                                    <precision>0.00025</precision>
                                </noise>
                            </y>
                            <z>
                                <noise type='gaussian'>
                                    <mean>0</mean>
                                    <stddev>0.009</stddev>
                                    <bias_mean>0.00075</bias_mean>
                                    <bias_stddev>0.005</bias_stddev>
                                    <dynamic_bias_stddev>0.00002</dynamic_bias_stddev>
                                    <dynamic_bias_correlation_time>400.0</dynamic_bias_correlation_time>
                                    <precision>0.00025</precision>
                                </noise>
                            </z>
                        </angular_velocity>
                        <linear_acceleration>
                            <x>
                                <noise type='gaussian'>
                                    <mean>0</mean>
                                    <stddev>0.021</stddev>
                                    <bias_mean>0.05</bias_mean>
                                    <bias_stddev>0.0075</bias_stddev>
                                    <dynamic_bias_stddev>0.000375</dynamic_bias_stddev>
                                    <dynamic_bias_correlation_time>175.0</dynamic_bias_correlation_time>
                                    <precision>0.005</precision>
                                </noise>
                            </x>
                            <y>
                                <noise type='gaussian'>
                                    <mean>0</mean>
                                    <stddev>0.021</stddev>
                                    <bias_mean>0.05</bias_mean>
                                    <bias_stddev>0.0075</bias_stddev>
                                    <dynamic_bias_stddev>0.000375</dynamic_bias_stddev>
                                    <dynamic_bias_correlation_time>175.0</dynamic_bias_correlation_time>
                                    <precision>0.005</precision>
                                </noise>
                            </y>
                            <z>
                                <noise type='gaussian'>
                                    <mean>0</mean>
                                    <stddev>0.021</stddev>
                                    <bias_mean>0.05</bias_mean>
                                    <bias_stddev>0.0075</bias_stddev>
                                    <dynamic_bias_stddev>0.000375</dynamic_bias_stddev>
                                    <dynamic_bias_correlation_time>175.0</dynamic_bias_correlation_time>
                                    <precision>0.005</precision>
                                </noise>
                            </z>
                        </linear_acceleration>
                    </imu>
                </sensor>
            </link>
        </model>

        <joint name="imu_joint" type="fixed">
            <parent>base_link</parent>
            <child>imu</child>
        </joint>

        <!-- AIR PRESSURE -->
        <model name='air_pressure'>
            <link name="internal">
                <inertial>
                    <mass>0.005</mass>
                    <inertia>
                        <ixx>8.33e-06</ixx>
                        <ixy>0</ixy>
                        <ixz>0</ixz>
                        <iyy>8.33e-06</iyy>
                        <iyz>0</iyz>
                        <izz>8.33e-06</izz>
                    </inertia>
                </inertial>
                <sensor name='air_pressure' type='air_pressure'>
                    <always_on>1</always_on>
                    <update_rate>20</update_rate>
                    <air_pressure>
                        <reference_altitude>0</reference_altitude>
                        <noise type='gaussian'>
                            <mean>0.00000008</mean>
                        </noise>
                    </air_pressure>
                </sensor>
            </link>
        </model>

        <joint name="air_pressure_joint" type="fixed">
            <parent>base_link</parent>
            <child>air_pressure</child>
        </joint>

        <!-- MAGNETOMETER -->
        <model name='magnetometer'>
            <link name="internal">
                <inertial>
                    <mass>0.005</mass>
                    <inertia>
                        <ixx>8.33e-06</ixx>
                        <ixy>0</ixy>
                        <ixz>0</ixz>
                        <iyy>8.33e-06</iyy>
                        <iyz>0</iyz>
                        <izz>8.33e-06</izz>
                    </inertia>
                </inertial>
                <sensor name='magnetometer' type='magnetometer'>
                    <always_on>1</always_on>
                    <update_rate>20</update_rate>
                    <magnetometer>
                        <x>
                            <noise type='gaussian'>
                                <mean>0.000000080</mean>
                                <bias_mean>0.000000400</bias_mean>
                            </noise>
                        </x>
                        <y>
                            <noise type='gaussian'>
                                <mean>0.000000080</mean>
                                <bias_mean>0.000000400</bias_mean>
                            </noise>
                        </y>
                        <z>
                            <noise type='gaussian'>
                                <mean>0.000000080</mean>
                                <bias_mean>0.000000400</bias_mean>
                            </noise>
                        </z>
                    </magnetometer>
                </sensor>
            </link>
        </model>

        <joint name="magnetometer_joint" type="fixed">
            <parent>base_link</parent>
            <child>magnetometer</child>
        </joint>

        <link name="rotor_0">
            <pose>0.247 0.1506 0.028 0.087267 0 0.523599</pose>
            <inertial>
                <pose>0 0 0 0 -0 0</pose>
                <mass>0.005</mass>
                <inertia>
                    <ixx>9.75e-07</ixx>
                    <ixy>0</ixy>
                    <ixz>0</ixz>
                    <iyy>8.13545e-05</iyy>
                    <iyz>0</iyz>
                    <izz>8.22545e-05</izz>
                </inertia>
            </inertial>
            <collision name="rotor_0_collision">
                <pose>0 0 0 0 -0 0</pose>
                <geometry>
                    <cylinder>
                        <length>0.005</length>
                        <radius>0.1397</radius>
                    </cylinder>
                </geometry>
                <surface>
                    <contact>
                        <ode/>
                    </contact>
                    <friction>
                        <ode/>
                    </friction>
                </surface>
            </collision>
            <visual name="rotor_0_visual">
                <pose>0 0 0 0 -0 0</pose>
                <geometry>
                    <mesh>
                        <scale>1 1 1</scale>
                        <uri>model://hexrotor_base/meshes/neo11_propeller_ccw.dae</uri>
                    </mesh>
                </geometry>
                <material>
                    <diffuse>1 0 0 1</diffuse>
                    <script>
                        <name>Gazebo/Red</name>
                        <uri>file://media/materials/scripts/gazebo.material</uri>
                    </script>
                </material>
                <cast_shadows>0</cast_shadows>
            </visual>
            <gravity>1</gravity>
            <velocity_decay/>
        </link>
        <joint name="rotor_0_joint" type="revolute">
            <child>rotor_0</child>
            <parent>base_link</parent>
            <axis>
                <xyz>0 0 1</xyz>
                <limit>
                    <lower>-1e+16</lower>
                    <upper>1e+16</upper>
                </limit>
                <dynamics>
                    <spring_reference>0</spring_reference>
                    <spring_stiffness>0</spring_stiffness>
                </dynamics>
            </axis>
        </joint>
        <link name="rotor_1">
            <pose>-0.00067 0.28929 0.028 0 -0.087267 0</pose>
            <inertial>
                <pose>0 0 0 0 -0 0</pose>
                <mass>0.005</mass>
                <inertia>
                    <ixx>9.75e-07</ixx>
                    <ixy>0</ixy>
                    <ixz>0</ixz>
                    <iyy>8.13545e-05</iyy>
                    <iyz>0</iyz>
                    <izz>8.22545e-05</izz>
                </inertia>
            </inertial>
            <collision name="rotor_1_collision">
                <pose>0 0 0 0 -0 0</pose>
                <geometry>
                    <cylinder>
                        <length>0.005</length>
                        <radius>0.1397</radius>
                    </cylinder>
                </geometry>
                <surface>
                    <contact>
                        <ode/>
                    </contact>
                    <friction>
                        <ode/>
                    </friction>
                </surface>
            </collision>
            <visual name="rotor_1_visual">
                <pose>0 0 0 0 -0 0</pose>
                <geometry>
                    <mesh>
                        <scale>1 1 1</scale>
                        <uri>model://hexrotor_base/meshes/neo11_propeller_cw.dae</uri>
                    </mesh>
                </geometry>
                <material>
                    <diffuse>0 0 1 1</diffuse>
                    <script>
                        <name>Gazebo/Blue</name>
                        <uri>file://media/materials/scripts/gazebo.material</uri>
                    </script>
                </material>
                <cast_shadows>0</cast_shadows>
            </visual>
            <gravity>1</gravity>
            <velocity_decay/>
        </link>
        <joint name="rotor_1_joint" type="revolute">
            <child>rotor_1</child>
            <parent>base_link</parent>
            <axis>
                <xyz>0 0 1</xyz>
                <limit>
                    <lower>-1e+16</lower>
                    <upper>1e+16</upper>
                </limit>
                <dynamics>
                    <spring_reference>0</spring_reference>
                    <spring_stiffness>0</spring_stiffness>
                </dynamics>
            </axis>
        </joint>
        <link name="rotor_2">
            <pose>-0.2501 0.1454 0.028 0.087267 -0 2.61799</pose>
            <inertial>
                <pose>0 0 0 0 -0 0</pose>
                <mass>0.005</mass>
                <inertia>
                    <ixx>9.75e-07</ixx>
                    <ixy>0</ixy>
                    <ixz>0</ixz>
                    <iyy>8.13545e-05</iyy>
                    <iyz>0</iyz>
                    <izz>8.22545e-05</izz>
                </inertia>
            </inertial>
            <collision name="rotor_2_collision">
                <pose>0 0 0 0 -0 0</pose>
                <geometry>
                    <cylinder>
                        <length>0.005</length>
                        <radius>0.1397</radius>
                    </cylinder>
                </geometry>
                <surface>
                    <contact>
                        <ode/>
                    </contact>
                    <friction>
                        <ode/>
                    </friction>
                </surface>
            </collision>
            <visual name="rotor_2_visual">
                <pose>0 0 0 0 -0 0</pose>
                <geometry>
                    <mesh>
                        <scale>1 1 1</scale>
                        <uri>model://hexrotor_base/meshes/neo11_propeller_ccw.dae</uri>
                    </mesh>
                </geometry>
                <material>
                    <diffuse>0 0 1 1</diffuse>
                    <script>
                        <name>Gazebo/Blue</name>
                        <uri>file://media/materials/scripts/gazebo.material</uri>
                    </script>
                </material>
                <cast_shadows>0</cast_shadows>
            </visual>
            <gravity>1</gravity>
            <velocity_decay/>
        </link>
        <joint name="rotor_2_joint" type="revolute">
            <child>rotor_2</child>
            <parent>base_link</parent>
            <axis>
                <xyz>0 0 1</xyz>
                <limit>
                    <lower>-1e+16</lower>
                    <upper>1e+16</upper>
                </limit>
                <dynamics>
                    <spring_reference>0</spring_reference>
                    <spring_stiffness>0</spring_stiffness>
                </dynamics>
            </axis>
        </joint>
        <link name="rotor_3">
            <pose>-0.2501 -0.1454 0.028 -0.087267 -0 -2.61799</pose>
            <inertial>
                <pose>0 0 0 0 -0 0</pose>
                <mass>0.005</mass>
                <inertia>
                    <ixx>9.75e-07</ixx>
                    <ixy>0</ixy>
                    <ixz>0</ixz>
                    <iyy>8.13545e-05</iyy>
                    <iyz>0</iyz>
                    <izz>8.22545e-05</izz>
                </inertia>
            </inertial>
            <collision name="rotor_3_collision">
                <pose>0 0 0 0 -0 0</pose>
                <geometry>
                    <cylinder>
                        <length>0.005</length>
                        <radius>0.1397</radius>
                    </cylinder>
                </geometry>
                <surface>
                    <contact>
                        <ode/>
                    </contact>
                    <friction>
                        <ode/>
                    </friction>
                </surface>
            </collision>
            <visual name="rotor_3_visual">
                <pose>0 0 0 0 -0 0</pose>
                <geometry>
                    <mesh>
                        <scale>1 1 1</scale>
                        <uri>model://hexrotor_base/meshes/neo11_propeller_cw.dae</uri>
                    </mesh>
                </geometry>
                <material>
                    <diffuse>0 0 1 1</diffuse>
                    <script>
                        <name>Gazebo/Blue</name>
                        <uri>file://media/materials/scripts/gazebo.material</uri>
                    </script>
                </material>
                <cast_shadows>0</cast_shadows>
            </visual>
            <gravity>1</gravity>
            <velocity_decay/>
        </link>
        <joint name="rotor_3_joint" type="revolute">
            <child>rotor_3</child>
            <parent>base_link</parent>
            <axis>
                <xyz>0 0 1</xyz>
                <limit>
                    <lower>-1e+16</lower>
                    <upper>1e+16</upper>
                </limit>
                <dynamics>
                    <spring_reference>0</spring_reference>
                    <spring_stiffness>0</spring_stiffness>
                </dynamics>
            </axis>
        </joint>
        <link name="rotor_4">
            <pose>-0.00067 -0.28929 0.028 -0 0.087267 -3.14159</pose>
            <inertial>
                <pose>0 0 0 0 -0 0</pose>
                <mass>0.005</mass>
                <inertia>
                    <ixx>9.75e-07</ixx>
                    <ixy>0</ixy>
                    <ixz>0</ixz>
                    <iyy>8.13545e-05</iyy>
                    <iyz>0</iyz>
                    <izz>8.22545e-05</izz>
                </inertia>
            </inertial>
            <collision name="rotor_4_collision">
                <pose>0 0 0 0 -0 0</pose>
                <geometry>
                    <cylinder>
                        <length>0.005</length>
                        <radius>0.1397</radius>
                    </cylinder>
                </geometry>
                <surface>
                    <contact>
                        <ode/>
                    </contact>
                    <friction>
                        <ode/>
                    </friction>
                </surface>
            </collision>
            <visual name="rotor_4_visual">
                <pose>0 0 0 0 -0 0</pose>
                <geometry>
                    <mesh>
                        <scale>1 1 1</scale>
                        <uri>model://hexrotor_base/meshes/neo11_propeller_ccw.dae</uri>
                    </mesh>
                </geometry>
                <material>
                    <diffuse>0 0 1 1</diffuse>
                    <script>
                        <name>Gazebo/Blue</name>
                        <uri>file://media/materials/scripts/gazebo.material</uri>
                    </script>
                </material>
                <cast_shadows>0</cast_shadows>
            </visual>
            <gravity>1</gravity>
            <velocity_decay/>
        </link>
        <joint name="rotor_4_joint" type="revolute">
            <child>rotor_4</child>
            <parent>base_link</parent>
            <axis>
                <xyz>0 0 1</xyz>
                <limit>
                    <lower>-1e+16</lower>
                    <upper>1e+16</upper>
                </limit>
                <dynamics>
                    <spring_reference>0</spring_reference>
                    <spring_stiffness>0</spring_stiffness>
                </dynamics>
            </axis>
        </joint>
        <link name="rotor_5">
            <pose>0.247 -0.1506 0.028 -0.087267 0 -0.523599</pose>
            <inertial>
                <pose>0 0 0 0 -0 0</pose>
                <mass>0.005</mass>
                <inertia>
                    <ixx>9.75e-07</ixx>
                    <ixy>0</ixy>
                    <ixz>0</ixz>
                    <iyy>8.13545e-05</iyy>
                    <iyz>0</iyz>
                    <izz>8.22545e-05</izz>
                </inertia>
            </inertial>
            <collision name="rotor_5_collision">
                <pose>0 0 0 0 -0 0</pose>
                <geometry>
                    <cylinder>
                        <length>0.005</length>
                        <radius>0.1397</radius>
                    </cylinder>
                </geometry>
                <surface>
                    <contact>
                        <ode/>
                    </contact>
                    <friction>
                        <ode/>
                    </friction>
                </surface>
            </collision>
            <visual name="rotor_5_visual">
                <pose>0 0 0 0 -0 0</pose>
                <geometry>
                    <mesh>
                        <scale>1 1 1</scale>
                        <uri>model://hexrotor_base/meshes/neo11_propeller_cw.dae</uri>
                    </mesh>
                </geometry>
                <material>
                    <diffuse>1 0 0 1</diffuse>
                    <script>
                        <name>Gazebo/Red</name>
                        <uri>file://media/materials/scripts/gazebo.material</uri>
                    </script>
                </material>
                <cast_shadows>0</cast_shadows>
            </visual>
            <gravity>1</gravity>
            <velocity_decay/>
        </link>
        <joint name="rotor_5_joint" type="revolute">
            <child>rotor_5</child>
            <parent>base_link</parent>
            <axis>
                <xyz>0 0 1</xyz>
                <limit>
                    <lower>-1e+16</lower>
                    <upper>1e+16</upper>
                </limit>
                <dynamics>
                    <spring_reference>0</spring_reference>
                    <spring_stiffness>0</spring_stiffness>
                </dynamics>
            </axis>
        </joint>

    </model>
</sdf>
