<?xml version='1.0' ?>
<!-- 
 ...........       ____  _ __
 |  ,-^-,  |      / __ )(_) /_______________ _____  ___
 | (  O  ) |     / __  / / __/ ___/ ___/ __ `/_  / / _ \
 | / ,..´  |    / /_/ / / /_/ /__/ /  / /_/ / / /_/  __/
    +.......   /_____/_/\__/\___/_/   \__,_/ /___/\___/
 
MIT License

Copyright (c) 2024 Bitcraze
-->

<sdf version='1.8'>
  <model name='crazyflie'>
    <pose>0 0 0.0 0 0 3.14</pose>
    <link name='base_link'>
      <inertial>
        <mass>0.025</mass>
        <inertia>
          <ixx>0.000016572</ixx>
          <iyy>0.000016656</iyy>
          <izz>0.000029262</izz>
        </inertia>
      </inertial>
      <collision name='base_link_inertia_collision'>
        <geometry>
          <box>
            <size>0.10 0.10 0.03</size>
          </box>
        </geometry>
      </collision>
      <visual name='base_link_inertia_visual'>
        <geometry>
          <mesh>
            <uri>model://crazyflie/meshes/cf2_assembly.dae</uri>
          </mesh>
        </geometry>
      </visual>
    </link>
    <link name='m1'>
      <pose>0.031 -0.031 0.021 0 0 0</pose>
      <inertial>
        <pose>0 0 0 0 -0 0</pose>
        <mass>0.0008</mass>
        <inertia>
          <ixx>8.33333E-09</ixx>
          <iyy>1.08333E-07</iyy>
          <izz>1.13333E-07</izz>
        </inertia>
      </inertial>
      <visual name='m1_visual'>
        <geometry>
          <mesh>
            <uri>model://crazyflie/meshes/ccw_prop.dae</uri>
          </mesh>
        </geometry>
      </visual>
    </link>
    <link name='m2'>
      <pose>-0.031 -0.031 0.021 0 0 0</pose>
      <inertial>
        <pose>0 0 0 0 -0 0</pose>
        <mass>0.0008</mass>
        <inertia>
          <ixx>8.33333E-09</ixx>
          <iyy>1.08333E-07</iyy>
          <izz>1.13333E-07</izz>
        </inertia>
      </inertial>
      <visual name='m2_visual'>
        <geometry>
          <mesh>
            <uri>model://crazyflie/meshes/cw_prop.dae</uri>
          </mesh>
        </geometry>
      </visual>
    </link>
    <link name='m3'>
      <pose>-0.031 0.031 0.021 0 0 0</pose>
      <inertial>
        <pose>0 0 0 0 -0 0</pose>
        <mass>0.0008</mass>
        <inertia>
          <ixx>8.33333E-09</ixx>
          <iyy>1.08333E-07</iyy>
          <izz>1.13333E-07</izz>
        </inertia>
      </inertial>
      <visual name='m3_visual'>
        <geometry>
          <mesh>
            <uri>model://crazyflie/meshes/ccw_prop.dae</uri>
          </mesh>
        </geometry>
      </visual>
    </link>
    <link name='m4'>
      <pose>0.031 0.031 0.021 0 0 0</pose>
      <inertial>
        <pose>0 0 0 0 -0 0</pose>
        <mass>0.0008</mass>
        <inertia>
          <ixx>8.33333E-09</ixx>
          <iyy>1.08333E-07</iyy>
          <izz>1.13333E-07</izz>
        </inertia>
      </inertial>
      <visual name='m4_visual'>
        <geometry>
          <mesh>
            <uri>model://crazyflie/meshes/cw_prop.dae</uri>
          </mesh>
        </geometry>
      </visual>
    </link>
    <joint name='m1_joint' type='revolute'>
      <child>m1</child>
      <parent>base_link</parent>
      <axis>
        <xyz>0 0 1</xyz>
      </axis>
    </joint>
    <joint name='m2_joint' type='revolute'>
      <child>m2</child>
      <parent>base_link</parent>
      <axis>
        <xyz>0 0 1</xyz>
      </axis>
    </joint>
    <joint name='m3_joint' type='revolute'>
      <child>m3</child>
      <parent>base_link</parent>
      <axis>
        <xyz>0 0 1</xyz>
      </axis>
    </joint>
    <joint name='m4_joint' type='revolute'>
      <child>m4</child>
      <parent>base_link</parent>
      <axis>
        <xyz>0 0 1</xyz>
      </axis>
    </joint>

    <!-- IMU -->
    <model name='imu'>
      <link name='internal'>
        <inertial>
          <mass>0.005</mass>
          <inertia>
            <ixx>8.33e-06</ixx>
            <ixy>0</ixy>
            <ixz>0</ixz>
            <iyy>8.33e-06</iyy>
            <iyz>0</iyz>
            <izz>8.33e-06</izz>
          </inertia>
        </inertial>
        <sensor name='imu' type='imu'>
          <always_on>1</always_on>
          <update_rate>250</update_rate>
          <imu>
            <angular_velocity>
              <x>
                <noise type='gaussian'>
                  <mean>0</mean>
                  <stddev>0.009</stddev>
                  <bias_mean>0.00075</bias_mean>
                  <bias_stddev>0.005</bias_stddev>
                  <dynamic_bias_stddev>0.00002</dynamic_bias_stddev>
                  <dynamic_bias_correlation_time>400.0</dynamic_bias_correlation_time>
                  <precision>0.00025</precision>
                </noise>
              </x>
              <y>
                <noise type='gaussian'>
                  <mean>0</mean>
                  <stddev>0.009</stddev>
                  <bias_mean>0.00075</bias_mean>
                  <bias_stddev>0.005</bias_stddev>
                  <dynamic_bias_stddev>0.00002</dynamic_bias_stddev>
                  <dynamic_bias_correlation_time>400.0</dynamic_bias_correlation_time>
                  <precision>0.00025</precision>
                </noise>
              </y>
              <z>
                <noise type='gaussian'>
                  <mean>0</mean>
                  <stddev>0.009</stddev>
                  <bias_mean>0.00075</bias_mean>
                  <bias_stddev>0.005</bias_stddev>
                  <dynamic_bias_stddev>0.00002</dynamic_bias_stddev>
                  <dynamic_bias_correlation_time>400.0</dynamic_bias_correlation_time>
                  <precision>0.00025</precision>
                </noise>
              </z>
            </angular_velocity>
            <linear_acceleration>
              <x>
                <noise type='gaussian'>
                  <mean>0</mean>
                  <stddev>0.021</stddev>
                  <bias_mean>0.05</bias_mean>
                  <bias_stddev>0.0075</bias_stddev>
                  <dynamic_bias_stddev>0.000375</dynamic_bias_stddev>
                  <dynamic_bias_correlation_time>175.0</dynamic_bias_correlation_time>
                  <precision>0.005</precision>
                </noise>
              </x>
              <y>
                <noise type='gaussian'>
                  <mean>0</mean>
                  <stddev>0.021</stddev>
                  <bias_mean>0.05</bias_mean>
                  <bias_stddev>0.0075</bias_stddev>
                  <dynamic_bias_stddev>0.000375</dynamic_bias_stddev>
                  <dynamic_bias_correlation_time>175.0</dynamic_bias_correlation_time>
                  <precision>0.005</precision>
                </noise>
              </y>
              <z>
                <noise type='gaussian'>
                  <mean>0</mean>
                  <stddev>0.021</stddev>
                  <bias_mean>0.05</bias_mean>
                  <bias_stddev>0.0075</bias_stddev>
                  <dynamic_bias_stddev>0.000375</dynamic_bias_stddev>
                  <dynamic_bias_correlation_time>175.0</dynamic_bias_correlation_time>
                  <precision>0.005</precision>
                </noise>
              </z>
            </linear_acceleration>
          </imu>
        </sensor>
      </link>
    </model>

  </model>
</sdf>