<?xml version="1.0" ?>
<sdf version="1.5">
  <model name="two_fingers_gripper">
    <plugin
        filename="ignition-gazebo-joint-position-controller-system"
        name="ignition::gazebo::systems::JointPositionController">
        <joint_name>r_gripper_l_finger_joint</joint_name>
        <topic>/model/drone0/joint/r_gripper_l_finger_joint/cmd_pos</topic>
    </plugin>
    <plugin
        filename="ignition-gazebo-joint-position-controller-system"
        name="ignition::gazebo::systems::JointPositionController">
        <joint_name>r_gripper_r_finger_joint</joint_name>
        <topic>/model/drone0/joint/r_gripper_r_finger_joint/cmd_pos</topic>
    </plugin>
      <plugin filename="ignition-gazebo-pose-publisher-system"
          name="ignition::gazebo::systems::PosePublisher">
          <publish_link_pose>true</publish_link_pose>
          <publish_collision_pose>false</publish_collision_pose>
          <publish_visual_pose>false</publish_visual_pose>
          <publish_nested_model_pose>true</publish_nested_model_pose>
          <publish_model_pose>true</publish_model_pose>
          <use_pose_vector_msg>true</use_pose_vector_msg>
          <static_publisher>false</static_publisher>
          <update_frequency>100</update_frequency>
      </plugin>
    <link name="r_wrist_roll_link">
      <pose>0.0 0.0 0.0 0.000000 -0.000000 0.000000</pose>
      <inertial>
        <pose>0.056408 0.000451 -0.001014 0.000000 -0.000000 0.000000</pose>
        <inertia>
          <ixx>0.011352</ixx>
          <ixy>-0.000016</ixy>
          <ixz>-0.000001</ixz>
          <iyy>0.011677</iyy>
          <iyz>-0.000001</iyz>
          <izz>0.011866</izz>
        </inertia>
        <mass>0.2</mass>
      </inertial>
      <collision name="r_wrist_roll_link_geom">
        <pose>0.000000 0.000000 0.000000 0.000000 -0.000000 0.000000</pose>
        <geometry>
          <box>
            <size>0.035 0.075 0.055</size>
          </box>
          <!-- <mesh>
            <uri>model://two_fingers_gripper/meshes/forearm_v0/wrist_roll_L.stl</uri>
            <scale>1.000000 1.000000 1.000000</scale>
            <uri>__default__</uri>
          </mesh> -->
        </geometry>
        <surface>
          <friction>
            <ode>
              <mu>0.000000</mu>
              <mu2>0.000000</mu2>
              <fdir1>0.000000 0.000000 0.000000</fdir1>
              <slip1>0.000000</slip1>
              <slip2>0.000000</slip2>
            </ode>
          </friction>
          <bounce>
            <restitution_coefficient>0.000000</restitution_coefficient>
            <threshold>100000.000000</threshold>
          </bounce>
          <contact>
            <ode>
              <soft_cfm>0.000000</soft_cfm>
              <soft_erp>0.200000</soft_erp>
              <kp>1000000000000.000000</kp>
              <kd>1.000000</kd>
              <max_vel>0.000000</max_vel>
              <min_depth>0.001000</min_depth>
            </ode>
          </contact>
        </surface>
        <laser_retro>0.000000</laser_retro>
      </collision>
      <visual name="r_wrist_roll_link_geom_visual">
        <pose>0.000000 0.000000 0.000000 0.000000 -0.000000 0.000000</pose>
        <geometry>
          <mesh>
            <uri>model://two_fingers_gripper/meshes/forearm_v0/wrist_roll.stl</uri>
            <scale>1.000000 1.000000 1.000000</scale>
            <uri>__default__</uri>
          </mesh>
        </geometry>
        <material>
          <script>
            <name>"loquesea"</name>
          <uri>
            model: //materials/textures
            </uri>
          </script>
        </material>
        <cast_shadows>1</cast_shadows>
        <laser_retro>0.000000</laser_retro>
        <transparency>0.000000</transparency>
      </visual>
      <visual name="r_wrist_roll_link_geom_r_gripper_palm_link_visual">
        <pose>0.000000 0.000000 0.000000 0.000000 -0.000000 0.000000</pose>
        <geometry>
          <mesh>
            <uri>model://two_fingers_gripper/meshes/gripper_v0/gripper_palm.dae</uri>
            <scale>1.000000 1.000000 1.000000</scale>
            <uri>__default__</uri>
          </mesh>
        </geometry>
        <cast_shadows>1</cast_shadows>
        <laser_retro>0.000000</laser_retro>
        <transparency>0.000000</transparency>
      </visual>
      <gravity>1</gravity>
      <self_collide>0</self_collide>
      <kinematic>0</kinematic>
      <velocity_decay />
    </link>
    <link name="r_gripper_l_finger_link">
      <pose>0.07691 0.01 0.0 0.000000 -0.000000 0.000000</pose>
      <inertial>
        <pose>0.035980 0.017300 -0.001640 0.000000 -0.000000 0.000000</pose>
        <inertia>
          <ixx>0.000078</ixx>
          <ixy>0.000001</ixy>
          <ixz>-0.000010</ixz>
          <iyy>0.000197</iyy>
          <iyz>-0.000003</iyz>
          <izz>0.000181</izz>
        </inertia>
        <mass>0.01</mass>
      </inertial>
      <collision name="r_gripper_l_finger_link_geom">
        <pose>0.000000 0.000000 0.000000 0.000000 -0.000000 0.000000</pose>
        <geometry>
            <box>
            <size>0.02 0.075 0.04</size>
          </box>
          <!-- <mesh>
            <uri>model://two_fingers_gripper/meshes/gripper_v0/l_finger.stl</uri>
            <scale>1.000000 1.000000 1.000000</scale>
            <uri>__default__</uri>
          </mesh> -->
        </geometry>
        <surface>
          <friction>
            <ode>
              <mu>500.000000</mu>
              <mu2>500.000000</mu2>
              <fdir1>0.000000 0.000000 0.000000</fdir1>
              <slip1>0.000000</slip1>
              <slip2>0.000000</slip2>
            </ode>
          </friction>
          <bounce>
            <restitution_coefficient>0.000000</restitution_coefficient>
            <threshold>100000.000000</threshold>
          </bounce>
          <contact>
            <ode>
              <soft_cfm>0.000000</soft_cfm>
              <soft_erp>0.200000</soft_erp>
              <kp>1000000.000000</kp>
              <kd>1.000000</kd>
              <max_vel>0.000000</max_vel>
              <min_depth>0.001000</min_depth>
            </ode>
          </contact>
        </surface>
        <laser_retro>0.000000</laser_retro>
      </collision>
      <visual name="r_gripper_l_finger_link_geom_visual">
        <pose>0.000000 0.000000 0.000000 0.000000 -0.000000 0.000000</pose>
        <geometry>
          <mesh>
            <uri>model://two_fingers_gripper/meshes/gripper_v0/l_finger.dae</uri>
            <scale>1.000000 1.000000 1.000000</scale>
            <uri>__default__</uri>
          </mesh>
        </geometry>
        <cast_shadows>1</cast_shadows>
        <laser_retro>0.000000</laser_retro>
        <transparency>0.000000</transparency>
      </visual>
      <gravity>1</gravity>
      <self_collide>0</self_collide>
      <kinematic>0</kinematic>
      <velocity_decay />
    </link>
    <link name="r_gripper_l_finger_tip_link">
      <pose>0.16828 0.01495 0.0 0.000000 -0.000000 0.000000</pose>
      <inertial>
        <pose>0.004230 0.002840 0.000000 0.000000 -0.000000 0.000000</pose>
        <inertia>
          <ixx>0.000008</ixx>
          <ixy>0.000006</ixy>
          <ixz>0.000000</ixz>
          <iyy>0.000010</iyy>
          <iyz>0.000000</iyz>
          <izz>0.000015</izz>
        </inertia>
        <mass>0.001</mass>
      </inertial>
      <collision name="r_gripper_l_finger_tip_link_geom">
        <pose>0.000000 0.000000 0.000000 0.000000 -0.000000 0.000000</pose>
        <geometry>
          <box>
              <size>0.02 0.03 0.02</size>
          </box> 
          <!-- <mesh>
            <uri>model://two_fingers_gripper/meshes/gripper_v0/l_finger_tip.stl</uri>
            <scale>1.000000 1.000000 1.000000</scale>
            <uri>__default__</uri>
          </mesh> -->
        </geometry>
        <surface>
          <friction>
            <ode>
              <mu>500.000000</mu>
              <mu2>500.000000</mu2>
              <fdir1>0.000000 0.000000 0.000000</fdir1>
              <slip1>0.000000</slip1>
              <slip2>0.000000</slip2>
            </ode>
          </friction>
          <bounce>
            <restitution_coefficient>0.000000</restitution_coefficient>
            <threshold>100000.000000</threshold>
          </bounce>
          <contact>
            <ode>
              <soft_cfm>0.000000</soft_cfm>
              <soft_erp>0.200000</soft_erp>
              <kp>10000000.000000</kp>
              <kd>1.000000</kd>
              <max_vel>0.000000</max_vel>
              <min_depth>0.001000</min_depth>
            </ode>
          </contact>
        </surface>
        <laser_retro>0.000000</laser_retro>
      </collision>
      <visual name="r_gripper_l_finger_tip_link_geom_visual">
        <pose>0.000000 0.000000 0.000000 0.000000 -0.000000 0.000000</pose>
        <geometry>
          <mesh>
            <uri>model://two_fingers_gripper/meshes/gripper_v0/l_finger_tip.dae</uri>
            <scale>1.000000 1.000000 1.000000</scale>
            <uri>__default__</uri>
          </mesh>
        </geometry>
        <cast_shadows>1</cast_shadows>
        <laser_retro>0.000000</laser_retro>
        <transparency>0.000000</transparency>
      </visual>
      <sensor name="r_gripper_l_finger_tip_contact_sensor" type="contact">
        <pose>0.000000 0.000000 0.000000 0.000000 -0.000000 0.000000</pose>
        <contact>
          <collision>r_gripper_l_finger_tip_link_geom</collision>
          <topic>__default_topic__</topic>
        </contact>
        <always_on>0</always_on>
        <update_rate>100.000000</update_rate>
        <visualize>0</visualize>
      </sensor>
      <gravity>1</gravity>
      <self_collide>0</self_collide>
      <kinematic>0</kinematic>
      <velocity_decay />
    </link>
    <link name="r_gripper_r_finger_link">
      <pose>0.07691 -0.01 0.0 0.000000 -0.000000 0.000000</pose>
      <inertial>
        <pose>0.035760 -0.017360 -0.000950 0.000000 -0.000000 0.000000</pose>
        <inertia>
          <ixx>0.000077</ixx>
          <ixy>-0.000002</ixy>
          <ixz>-0.000008</ixz>
          <iyy>0.000198</iyy>
          <iyz>0.000002</iyz>
          <izz>0.000181</izz>
        </inertia>
        <mass>0.01</mass>
      </inertial>
      <collision name="r_gripper_r_finger_link_geom">
        <pose>0.000000 0.000000 0.000000 -3.141590 -0.000000 0.000000</pose>
        <geometry>
          <box>
              <size>0.02 0.03 0.04</size>
          </box>          
          <!-- <mesh>
            <uri>model://two_fingers_gripper/meshes/gripper_v0/l_finger.stl</uri>
            <scale>1.000000 1.000000 1.000000</scale>
            <uri>__default__</uri>
          </mesh> -->
        </geometry>
        <surface>
          <friction>
            <ode>
              <mu>500.000000</mu>
              <mu2>500.000000</mu2>
              <fdir1>0.000000 0.000000 0.000000</fdir1>
              <slip1>0.000000</slip1>
              <slip2>0.000000</slip2>
            </ode>
          </friction>
          <bounce>
            <restitution_coefficient>0.000000</restitution_coefficient>
            <threshold>100000.000000</threshold>
          </bounce>
          <contact>
            <ode>
              <soft_cfm>0.000000</soft_cfm>
              <soft_erp>0.200000</soft_erp>
              <kp>1000000.000000</kp>
              <kd>1.000000</kd>
              <max_vel>0.000000</max_vel>
              <min_depth>0.001000</min_depth>
            </ode>
          </contact>
        </surface>
        <laser_retro>0.000000</laser_retro>
      </collision>
      <visual name="r_gripper_r_finger_link_geom_visual">
        <pose>0.000000 0.000000 0.000000 -3.141590 0.000000 0.000000</pose>
        <geometry>
          <mesh>
            <uri>model://two_fingers_gripper/meshes/gripper_v0/l_finger.dae</uri>
            <scale>1.000000 1.000000 1.000000</scale>
            <uri>__default__</uri>
          </mesh>
        </geometry>
        <cast_shadows>1</cast_shadows>
        <laser_retro>0.000000</laser_retro>
        <transparency>0.000000</transparency>
      </visual>
      <gravity>1</gravity>
      <self_collide>0</self_collide>
      <kinematic>0</kinematic>
      <velocity_decay />
    </link>
    <link name="r_gripper_r_finger_tip_link">
      <pose>0.16828 -0.01495 0.0 0.000000 -0.000000 0.000000</pose>
      <inertial>
        <pose>0.004230 -0.002840 0.000000 0.000000 -0.000000 0.000000</pose>
        <inertia>
          <ixx>0.000008</ixx>
          <ixy>-0.000006</ixy>
          <ixz>0.000000</ixz>
          <iyy>0.000010</iyy>
          <iyz>0.000000</iyz>
          <izz>0.000015</izz>
        </inertia>
        <mass>0.001</mass>
      </inertial>
      <collision name="r_gripper_r_finger_tip_link_geom">
        <pose>0.000000 0.000000 0.000000 -3.141590 -0.000000 0.000000</pose>
        <geometry>
           <box>
              <size>0.02 0.03 0.02</size>
          </box> 
          <!-- <mesh>
            <uri>model://two_fingers_gripper/meshes/gripper_v0/l_finger_tip.stl</uri>
            <scale>1.000000 1.000000 1.000000</scale>
            <uri>__default__</uri> -->
          <!-- </mesh> -->
        </geometry>
        <surface>
          <friction>
            <ode>
              <mu>500.000000</mu>
              <mu2>500.000000</mu2>
              <fdir1>0.000000 0.000000 0.000000</fdir1>
              <slip1>0.000000</slip1>
              <slip2>0.000000</slip2>
            </ode>
          </friction>
          <bounce>
            <restitution_coefficient>0.000000</restitution_coefficient>
            <threshold>100000.000000</threshold>
          </bounce>
          <contact>
            <ode>
              <soft_cfm>0.000000</soft_cfm>
              <soft_erp>0.200000</soft_erp>
              <kp>10000000.000000</kp>
              <kd>1.000000</kd>
              <max_vel>0.000000</max_vel>
              <min_depth>0.001000</min_depth>
            </ode>
          </contact>
        </surface>
        <laser_retro>0.000000</laser_retro>
      </collision>
      <visual name="r_gripper_r_finger_tip_link_geom_visual">
        <pose>0.000000 0.000000 0.000000 -3.141590 0.000000 0.000000</pose>
        <geometry>
          <mesh>
            <uri>model://two_fingers_gripper/meshes/gripper_v0/l_finger_tip.dae</uri>
            <scale>1.000000 1.000000 1.000000</scale>
            <uri>__default__</uri>
          </mesh>
        </geometry>
        <cast_shadows>1</cast_shadows>
        <laser_retro>0.000000</laser_retro>
        <transparency>0.000000</transparency>
      </visual>
      <sensor name="r_gripper_r_finger_tip_contact_sensor" type="contact">
        <pose>0.000000 0.000000 0.000000 0.000000 -0.000000 0.000000</pose>
        <contact>
          <collision>r_gripper_r_finger_tip_link_geom</collision>
          <topic>__default_topic__</topic>
        </contact>
        <always_on>0</always_on>
        <update_rate>100.000000</update_rate>
        <visualize>0</visualize>
      </sensor>
      <gravity>1</gravity>
      <self_collide>0</self_collide>
      <kinematic>0</kinematic>
      <velocity_decay />
    </link>
    <joint name="r_gripper_l_finger_joint" type="revolute">
      <pose>0.000000 0.000000 0.000000 0.000000 -0.000000 0.000000</pose>
      <parent>r_wrist_roll_link</parent>
      <child>r_gripper_l_finger_link</child>
    </joint>
    <joint name="r_gripper_l_finger_tip_joint" type="fixed">
      <pose>0.000000 0.000000 0.000000 0.000000 -0.000000 0.000000</pose>
      <parent>r_gripper_l_finger_link</parent>
      <child>r_gripper_l_finger_tip_link</child>
    </joint>
    <joint name="r_gripper_r_finger_joint" type="revolute">
      <pose>0.000000 0.000000 0.000000 0.000000 -0.000000 0.000000</pose>
      <parent>r_wrist_roll_link</parent>
      <child>r_gripper_r_finger_link</child>
    </joint>
    <joint name="r_gripper_r_finger_tip_joint" type="fixed">
      <pose>0.000000 0.000000 0.000000 0.000000 -0.000000 0.000000</pose>
      <parent>r_gripper_r_finger_link</parent>
      <child>r_gripper_r_finger_tip_link</child>
    </joint>
  
  </model>
</sdf>